Workbook

Sheet Инструкция
A1: Фаза 1 — выбор концепции проекта (нечёткий коллективный TOPSIS и МАИ)
A3: Оценки всех трёх экспертов — из переписки. Веса предложены для расчёта. Парные сравнения МАИ сформированы из средних m и приняты командой.
A5: Что заполнять (синий шрифт на жёлтом фоне):
A6: 1. «Концепции» — названия и описания 4 концепций и 4 критериев; тип критерия: max (чем больше, тем лучше) или min (чем меньше, тем лучше).
A7: 2. «Оценки» — у каждого эксперта: оценка каждой концепции по каждому критерию тройкой (l — пессимистичная, m — наиболее ожидаемая, u — оптимистичная), шкала 1–10; строка «Вес критерия» — тройка на шкале 0–1. Должно выполняться l ≤ m ≤ u.
A8: 3. «МАИ» — только верхний треугольник матриц парных сравнений по шкале Саати (1, 3, 5, 7, 9 и промежуточные; 1/3 и т. п. — если столбец важнее строки). Нижний треугольник считается сам.
A9: Для критериев типа min в матрицах сравнения концепций ставьте предпочтение: дешевле/проще = лучше.
A11: Всё остальное — формулы (чёрный шрифт), пересчитываются автоматически. Итоги — на листе «Итог».
A13: Метод TOPSIS (нечёткий, коллективный):
A14: • Агрегирование оценок экспертов: l = MIN(l_k), m = СРЗНАЧ(m_k), u = MAX(u_k); так же для весов.
A15: • Нормализация: для max — (l/u*, m/u*, u/u*), u* = максимум u по критерию; для min — (l⁻/u, l⁻/m, l⁻/l), l⁻ = минимум l.
A16: • Взвешенная матрица: v = r ⊗ w (покомпонентное произведение троек).
... A25: • Глобальный приоритет концепции = Σ (вес критерия × локальный приоритет концепции по критерию).

Sheet Концепции
A1: Концепции и критерии
A3: Код | B3: Концепция | C3: Описание
A4: A1 | B4: Система управления командными задачами и рабочими процессами | C4: Сервис для совместного ведения проектов: распределения задач, контроля сроков и отслеживания рабочих процессов команды.
A5: A2 | B5: Система персонального и семейного финансового учёта | C5: Приложение для учёта личных и семейных доходов и расходов, планирования бюджета и анализа трат.
A6: A3 | B6: Система онлайн-бронирования услуг и управления записями | C6: Сервис для выбора услуги и свободного времени, бронирования записи и управления расписанием исполнителя.
A7: A4 | B7: Система планирования тренировок и отслеживания физической активности | C7: Приложение для составления планов тренировок, записи выполненных упражнений и отслеживания активности и прогресса.
A10: Код | B10: Критерий | C10: Тип (max/min) | D10: Экономические результаты
A11: K1 | B11: Пользовательская ценность | C11: max | D11: Выгоды (benefits)
A12: K2 | B12: Широта целевой аудитории | C12: max | D12: Выгоды (benefits)
A13: K3 | B13: Сложность освоения продукта | C13: min | D13: Затраты (costs)
A14: K4 | B14: Количество действий для выполнения основных сценариев | C14: min | D14: Затраты (costs)
A16: Источник: | B16: https://github.com/kostikbezopasnost/project_management/blob/main/phase_1/concepts/README.md

Sheet Оценки
A1: Экспертные оценки: нечёткие трёхточечные числа (l, m, u)
A3: Эксперт 1 | B3: Золотухин Константин. В.
B4: Концепция | C4: =Концепции!$B$11 -> Пользовательская ценность | F4: =Концепции!$B$12 -> Широта целевой аудитории | I4: =Концепции!$B$13 -> Сложность освоения продукта | L4: =Концепции!$B$14 -> Количество действий для выполнения основных сценариев
C5: l | D5: m | E5: u | F5: l | G5: m | H5: u | I5: l | J5: m | K5: u | L5: l | M5: m | N5: u
A6: A1 | B6: =Концепции!$B$4 -> Система управления командными задачами и рабочими процессами | C6: 5 | D6: 8 | E6: 9 | F6: 8 | G6: 9 | H6: 10 | I6: 5 | J6: 6 | K6: 7 | L6: 5 | M6: 7 | N6: 8
A7: A2 | B7: =Концепции!$B$5 -> Система персонального и семейного финансового учёта | C7: 8 | D7: 9 | E7: 10 | F7: 8 | G7: 9 | H7: 10 | I7: 5 | J7: 6 | K7: 7 | L7: 6 | M7: 7 | N7: 8
A8: A3 | B8: =Концепции!$B$6 -> Система онлайн-бронирования услуг и управления записями | C8: 7 | D8: 8 | E8: 9 | F8: 8 | G8: 9 | H8: 10 | I8: 4 | J8: 5 | K8: 7 | L8: 4 | M8: 5 | N8: 6
A9: A4 | B9: =Концепции!$B$7 -> Система планирования тренировок и отслеживания физической активности | C9: 8 | D9: 9 | E9: 10 | F9: 7 | G9: 8 | H9: 9 | I9: 4 | J9: 5 | K9: 6 | L9: 5 | M9: 6 | N9: 7
A10: w | B10: Вес критерия (0–1) | C10: 0.8 | D10: 0.9 | E10: 1 | F10: 0.8 | G10: 0.9 | H10: 1 | I10: 0.7 | J10: 0.8 | K10: 0.9 | L10: 0.5 | M10: 0.6 | N10: 0.7
A12: Эксперт 2 | B12: Сибирко Олег. В.
B13: Концепция | C13: =Концепции!$B$11 -> Пользовательская ценность | F13: =Концепции!$B$12 -> Широта целевой аудитории | I13: =Концепции!$B$13 -> Сложность освоения продукта | L13: =Концепции!$B$14 -> Количество действий для выполнения основных сценариев
C14: l | D14: m | E14: u | F14: l | G14: m | H14: u | I14: l | J14: m | K14: u | L14: l | M14: m | N14: u
A15: A1 | B15: =Концепции!$B$4 -> Система управления командными задачами и рабочими процессами | C15: 5 | D15: 6 | E15: 7 | F15: 6 | G15: 7 | H15: 8 | I15: 2 | J15: 4 | K15: 5 | L15: 4 | M15: 5 | N15: 7
A16: A2 | B16: =Концепции!$B$5 -> Система персонального и семейного финансового учёта | C16: 8 | D16: 9 | E16: 10 | F16: 8 | G16: 9 | H16: 10 | I16: 4 | J16: 6 | K16: 7 | L16: 3 | M16: 4 | N16: 6
A17: A3 | B17: =Концепции!$B$6 -> Система онлайн-бронирования услуг и управления записями | C17: 7 | D17: 8 | E17: 10 | F17: 6 | G17: 8 | H17: 9 | I17: 5 | J17: 7 | K17: 9 | L17: 6 | M17: 8 | N17: 9
A18: A4 | B18: =Концепции!$B$7 -> Система планирования тренировок и отслеживания физической активности | C18: 5 | D18: 7 | E18: 8 | F18: 7 | G18: 8 | H18: 9 | I18: 4 | J18: 5 | K18: 7 | L18: 3 | M18: 5 | N18: 6
A19: w | B19: Вес критерия (0–1) | C19: 0.8 | D19: 0.9 | E19: 1 | F19: 0.7 | G19: 0.8 | H19: 0.9 | I19: 0.8 | J19: 0.9 | K19: 1 | L19: 0.6 | M19: 0.7 | N19: 0.8
A21: Эксперт 3 | B21: Богданов Андрей Д.
B22: Концепция | C22: =Концепции!$B$11 -> Пользовательская ценность | F22: =Концепции!$B$12 -> Широта целевой аудитории | I22: =Концепции!$B$13 -> Сложность освоения продукта | L22: =Концепции!$B$14 -> Количество действий для выполнения основных сценариев
C23: l | D23: m | E23: u | F23: l | G23: m | H23: u | I23: l | J23: m | K23: u | L23: l | M23: m | N23: u
A24: A1 | B24: =Концепции!$B$4 -> Система управления командными задачами и рабочими процессами | C24: 6 | D24: 8 | E24: 10 | F24: 5 | G24: 7 | H24: 9 | I24: 4 | J24: 6 | K24: 8 | L24: 3 | M24: 5 | N24: 7
A25: A2 | B25: =Концепции!$B$5 -> Система персонального и семейного финансового учёта | C25: 7 | D25: 9 | E25: 10 | F25: 8 | G25: 10 | H25: 10 | I25: 6 | J25: 8 | K25: 10 | L25: 4 | M25: 6 | N25: 8
A26: A3 | B26: =Концепции!$B$6 -> Система онлайн-бронирования услуг и управления записями | C26: 7 | D26: 9 | E26: 10 | F26: 7 | G26: 9 | H26: 10 | I26: 2 | J26: 4 | K26: 6 | L26: 2 | M26: 4 | N26: 6
A27: A4 | B27: =Концепции!$B$7 -> Система планирования тренировок и отслеживания физической активности | C27: 5 | D27: 7 | E27: 9 | F27: 3 | G27: 5 | H27: 7 | I27: 2 | J27: 4 | K27: 6 | L27: 2 | M27: 4 | N27: 6
A28: w | B28: Вес критерия (0–1) | C28: 0.7 | D28: 0.9 | E28: 1 | F28: 0.6 | G28: 0.8 | H28: 1 | I28: 0.7 | J28: 0.9 | K28: 1 | L28: 0.4 | M28: 0.6 | N28: 0.8

Sheet TOPSIS
A1: Нечёткий коллективный метод TOPSIS
A3: 1. Агрегированная матрица (l = MIN, m = СРЗНАЧ, u = MAX по экспертам)
B4: Концепция | C4: =Концепции!$B$11 -> Пользовательская ценность | F4: =Концепции!$B$12 -> Широта целевой аудитории | I4: =Концепции!$B$13 -> Сложность освоения продукта | L4: =Концепции!$B$14 -> Количество действий для выполнения основных сценариев
C5: l | D5: m | E5: u | F5: l | G5: m | H5: u | I5: l | J5: m | K5: u | L5: l | M5: m | N5: u
A6: A1 | B6: =Концепции!$B$4 -> Система управления командными задачами и рабочими процессами | C6: =MIN(Оценки!$C$6,Оценки!$C$15,Оценки!$C$24) -> 5 | D6: =AVERAGE(Оценки!$D$6,Оценки!$D$15,Оценки!$D$24) -> 7.3333333 | E6: =MAX(Оценки!$E$6,Оценки!$E$15,Оценки!$E$24) -> 10 | F6: =MIN(Оценки!$F$6,Оценки!$F$15,Оценки!$F$24) -> 5 | G6: =AVERAGE(Оценки!$G$6,Оценки!$G$15,Оценки!$G$24) -> 7.6666667 | H6: =MAX(Оценки!$H$6,Оценки!$H$15,Оценки!$H$24) -> 10 | I6: =MIN(Оценки!$I$6,Оценки!$I$15,Оценки!$I$24) -> 2 | J6: =AVERAGE(Оценки!$J$6,Оценки!$J$15,Оценки!$J$24) -> 5.3333333 | K6: =MAX(Оценки!$K$6,Оценки!$K$15,Оценки!$K$24) -> 8 | L6: =MIN(Оценки!$L$6,Оценки!$L$15,Оценки!$L$24) -> 3 | M6: =AVERAGE(Оценки!$M$6,Оценки!$M$15,Оценки!$M$24) -> 5.6666667 | N6: =MAX(Оценки!$N$6,Оценки!$N$15,Оценки!$N$24) -> 8
A7: A2 | B7: =Концепции!$B$5 -> Система персонального и семейного финансового учёта | C7: =MIN(Оценки!$C$7,Оценки!$C$16,Оценки!$C$25) -> 7 | D7: =AVERAGE(Оценки!$D$7,Оценки!$D$16,Оценки!$D$25) -> 9 | E7: =MAX(Оценки!$E$7,Оценки!$E$16,Оценки!$E$25) -> 10 | F7: =MIN(Оценки!$F$7,Оценки!$F$16,Оценки!$F$25) -> 8 | G7: =AVERAGE(Оценки!$G$7,Оценки!$G$16,Оценки!$G$25) -> 9.3333333 | H7: =MAX(Оценки!$H$7,Оценки!$H$16,Оценки!$H$25) -> 10 | I7: =MIN(Оценки!$I$7,Оценки!$I$16,Оценки!$I$25) -> 4 | J7: =AVERAGE(Оценки!$J$7,Оценки!$J$16,Оценки!$J$25) -> 6.6666667 | K7: =MAX(Оценки!$K$7,Оценки!$K$16,Оценки!$K$25) -> 10 | L7: =MIN(Оценки!$L$7,Оценки!$L$16,Оценки!$L$25) -> 3 | M7: =AVERAGE(Оценки!$M$7,Оценки!$M$16,Оценки!$M$25) -> 5.6666667 | N7: =MAX(Оценки!$N$7,Оценки!$N$16,Оценки!$N$25) -> 8
A8: A3 | B8: =Концепции!$B$6 -> Система онлайн-бронирования услуг и управления записями | C8: =MIN(Оценки!$C$8,Оценки!$C$17,Оценки!$C$26) -> 7 | D8: =AVERAGE(Оценки!$D$8,Оценки!$D$17,Оценки!$D$26) -> 8.3333333 | E8: =MAX(Оценки!$E$8,Оценки!$E$17,Оценки!$E$26) -> 10 | F8: =MIN(Оценки!$F$8,Оценки!$F$17,Оценки!$F$26) -> 6 | G8: =AVERAGE(Оценки!$G$8,Оценки!$G$17,Оценки!$G$26) -> 8.6666667 | H8: =MAX(Оценки!$H$8,Оценки!$H$17,Оценки!$H$26) -> 10 | I8: =MIN(Оценки!$I$8,Оценки!$I$17,Оценки!$I$26) -> 2 | J8: =AVERAGE(Оценки!$J$8,Оценки!$J$17,Оценки!$J$26) -> 5.3333333 | K8: =MAX(Оценки!$K$8,Оценки!$K$17,Оценки!$K$26) -> 9 | L8: =MIN(Оценки!$L$8,Оценки!$L$17,Оценки!$L$26) -> 2 | M8: =AVERAGE(Оценки!$M$8,Оценки!$M$17,Оценки!$M$26) -> 5.6666667 | N8: =MAX(Оценки!$N$8,Оценки!$N$17,Оценки!$N$26) -> 9
A9: A4 | B9: =Концепции!$B$7 -> Система планирования тренировок и отслеживания физической активности | C9: =MIN(Оценки!$C$9,Оценки!$C$18,Оценки!$C$27) -> 5 | D9: =AVERAGE(Оценки!$D$9,Оценки!$D$18,Оценки!$D$27) -> 7.6666667 | E9: =MAX(Оценки!$E$9,Оценки!$E$18,Оценки!$E$27) -> 10 | F9: =MIN(Оценки!$F$9,Оценки!$F$18,Оценки!$F$27) -> 3 | G9: =AVERAGE(Оценки!$G$9,Оценки!$G$18,Оценки!$G$27) -> 7 | H9: =MAX(Оценки!$H$9,Оценки!$H$18,Оценки!$H$27) -> 9 | I9: =MIN(Оценки!$I$9,Оценки!$I$18,Оценки!$I$27) -> 2 | J9: =AVERAGE(Оценки!$J$9,Оценки!$J$18,Оценки!$J$27) -> 4.6666667 | K9: =MAX(Оценки!$K$9,Оценки!$K$18,Оценки!$K$27) -> 7 | L9: =MIN(Оценки!$L$9,Оценки!$L$18,Оценки!$L$27) -> 2 | M9: =AVERAGE(Оценки!$M$9,Оценки!$M$18,Оценки!$M$27) -> 5 | N9: =MAX(Оценки!$N$9,Оценки!$N$18,Оценки!$N$27) -> 7
A10: w | B10: Агрегированный вес | C10: =MIN(Оценки!$C$10,Оценки!$C$19,Оценки!$C$28) -> 0.7 | D10: =AVERAGE(Оценки!$D$10,Оценки!$D$19,Оценки!$D$28) -> 0.9 | E10: =MAX(Оценки!$E$10,Оценки!$E$19,Оценки!$E$28) -> 1 | F10: =MIN(Оценки!$F$10,Оценки!$F$19,Оценки!$F$28) -> 0.6 | G10: =AVERAGE(Оценки!$G$10,Оценки!$G$19,Оценки!$G$28) -> 0.83333333 | H10: =MAX(Оценки!$H$10,Оценки!$H$19,Оценки!$H$28) -> 1 | I10: =MIN(Оценки!$I$10,Оценки!$I$19,Оценки!$I$28) -> 0.7 | J10: =AVERAGE(Оценки!$J$10,Оценки!$J$19,Оценки!$J$28) -> 0.86666667 | K10: =MAX(Оценки!$K$10,Оценки!$K$19,Оценки!$K$28) -> 1 | L10: =MIN(Оценки!$L$10,Оценки!$L$19,Оценки!$L$28) -> 0.4 | M10: =AVERAGE(Оценки!$M$10,Оценки!$M$19,Оценки!$M$28) -> 0.63333333 | N10: =MAX(Оценки!$N$10,Оценки!$N$19,Оценки!$N$28) -> 0.8
B11: Тип критерия | C11: =Концепции!$C$11 -> max | F11: =Концепции!$C$12 -> max | I11: =Концепции!$C$13 -> min | L11: =Концепции!$C$14 -> min
B12: u* = max u | C12: =MAX(E6:E9) -> 10 | F12: =MAX(H6:H9) -> 10 | I12: =MAX(K6:K9) -> 10 | L12: =MAX(N6:N9) -> 9
B13: l⁻ = min l | C13: =MIN(C6:C9) -> 5 | F13: =MIN(F6:F9) -> 3 | I13: =MIN(I6:I9) -> 2 | L13: =MIN(L6:L9) -> 2
A15: 2. Нормализованная матрица
B16: Концепция | C16: =Концепции!$B$11 -> Пользовательская ценность | F16: =Концепции!$B$12 -> Широта целевой аудитории | I16: =Концепции!$B$13 -> Сложность освоения продукта | L16: =Концепции!$B$14 -> Количество действий для выполнения основных сценариев
C17: l | D17: m | E17: u | F17: l | G17: m | H17: u | I17: l | J17: m | K17: u | L17: l | M17: m | N17: u
A18: A1 | B18: =Концепции!$B$4 -> Система управления командными задачами и рабочими процессами | C18: =IF($C$11="max",C6/$C$12,$C$13/E6) -> 0.5 | D18: =IF($C$11="max",D6/$C$12,$C$13/D6) -> 0.73333333 | E18: =IF($C$11="max",E6/$C$12,$C$13/C6) -> 1 | F18: =IF($F$11="max",F6/$F$12,$F$13/H6) -> 0.5 | G18: =IF($F$11="max",G6/$F$12,$F$13/G6) -> 0.76666667 | H18: =IF($F$11="max",H6/$F$12,$F$13/F6) -> 1 | I18: =IF($I$11="max",I6/$I$12,$I$13/K6) -> 0.25 | J18: =IF($I$11="max",J6/$I$12,$I$13/J6) -> 0.375 | K18: =IF($I$11="max",K6/$I$12,$I$13/I6) -> 1 | L18: =IF($L$11="max",L6/$L$12,$L$13/N6) -> 0.25 | M18: =IF($L$11="max",M6/$L$12,$L$13/M6) -> 0.35294118 | N18: =IF($L$11="max",N6/$L$12,$L$13/L6) -> 0.66666667
A19: A2 | B19: =Концепции!$B$5 -> Система персонального и семейного финансового учёта | C19: =IF($C$11="max",C7/$C$12,$C$13/E7) -> 0.7 | D19: =IF($C$11="max",D7/$C$12,$C$13/D7) -> 0.9 | E19: =IF($C$11="max",E7/$C$12,$C$13/C7) -> 1 | F19: =IF($F$11="max",F7/$F$12,$F$13/H7) -> 0.8 | G19: =IF($F$11="max",G7/$F$12,$F$13/G7) -> 0.93333333 | H19: =IF($F$11="max",H7/$F$12,$F$13/F7) -> 1 | I19: =IF($I$11="max",I7/$I$12,$I$13/K7) -> 0.2 | J19: =IF($I$11="max",J7/$I$12,$I$13/J7) -> 0.3 | K19: =IF($I$11="max",K7/$I$12,$I$13/I7) -> 0.5 | L19: =IF($L$11="max",L7/$L$12,$L$13/N7) -> 0.25 | M19: =IF($L$11="max",M7/$L$12,$L$13/M7) -> 0.35294118 | N19: =IF($L$11="max",N7/$L$12,$L$13/L7) -> 0.66666667
A20: A3 | B20: =Концепции!$B$6 -> Система онлайн-бронирования услуг и управления записями | C20: =IF($C$11="max",C8/$C$12,$C$13/E8) -> 0.7 | D20: =IF($C$11="max",D8/$C$12,$C$13/D8) -> 0.83333333 | E20: =IF($C$11="max",E8/$C$12,$C$13/C8) -> 1 | F20: =IF($F$11="max",F8/$F$12,$F$13/H8) -> 0.6 | G20: =IF($F$11="max",G8/$F$12,$F$13/G8) -> 0.86666667 | H20: =IF($F$11="max",H8/$F$12,$F$13/F8) -> 1 | I20: =IF($I$11="max",I8/$I$12,$I$13/K8) -> 0.22222222 | J20: =IF($I$11="max",J8/$I$12,$I$13/J8) -> 0.375 | K20: =IF($I$11="max",K8/$I$12,$I$13/I8) -> 1 | L20: =IF($L$11="max",L8/$L$12,$L$13/N8) -> 0.22222222 | M20: =IF($L$11="max",M8/$L$12,$L$13/M8) -> 0.35294118 | N20: =IF($L$11="max",N8/$L$12,$L$13/L8) -> 1
A21: A4 | B21: =Концепции!$B$7 -> Система планирования тренировок и отслеживания физической активности | C21: =IF($C$11="max",C9/$C$12,$C$13/E9) -> 0.5 | D21: =IF($C$11="max",D9/$C$12,$C$13/D9) -> 0.76666667 | E21: =IF($C$11="max",E9/$C$12,$C$13/C9) -> 1 | F21: =IF($F$11="max",F9/$F$12,$F$13/H9) -> 0.3 | G21: =IF($F$11="max",G9/$F$12,$F$13/G9) -> 0.7 | H21: =IF($F$11="max",H9/$F$12,$F$13/F9) -> 0.9 | I21: =IF($I$11="max",I9/$I$12,$I$13/K9) -> 0.28571429 | J21: =IF($I$11="max",J9/$I$12,$I$13/J9) -> 0.42857143 | K21: =IF($I$11="max",K9/$I$12,$I$13/I9) -> 1 | L21: =IF($L$11="max",L9/$L$12,$L$13/N9) -> 0.28571429 | M21: =IF($L$11="max",M9/$L$12,$L$13/M9) -> 0.4 | N21: =IF($L$11="max",N9/$L$12,$L$13/L9) -> 1
A23: 3. Взвешенная нормализованная матрица v = r ⊗ w
B24: Концепция | C24: =Концепции!$B$11 -> Пользовательская ценность | F24: =Концепции!$B$12 -> Широта целевой аудитории | I24: =Концепции!$B$13 -> Сложность освоения продукта | L24: =Концепции!$B$14 -> Количество действий для выполнения основных сценариев
C25: l | D25: m | E25: u | F25: l | G25: m | H25: u | I25: l | J25: m | K25: u | L25: l | M25: m | N25: u
A26: A1 | B26: =Концепции!$B$4 -> Система управления командными задачами и рабочими процессами | C26: =C18*$C$10 -> 0.35 | D26: =D18*$D$10 -> 0.66 | E26: =E18*$E$10 -> 1 | F26: =F18*$F$10 -> 0.3 | G26: =G18*$G$10 -> 0.63888889 | H26: =H18*$H$10 -> 1 | I26: =I18*$I$10 -> 0.175 | J26: =J18*$J$10 -> 0.325 | K26: =K18*$K$10 -> 1 | L26: =L18*$L$10 -> 0.1 | M26: =M18*$M$10 -> 0.22352941 | N26: =N18*$N$10 -> 0.53333333
A27: A2 | B27: =Концепции!$B$5 -> Система персонального и семейного финансового учёта | C27: =C19*$C$10 -> 0.49 | D27: =D19*$D$10 -> 0.81 | E27: =E19*$E$10 -> 1 | F27: =F19*$F$10 -> 0.48 | G27: =G19*$G$10 -> 0.77777778 | H27: =H19*$H$10 -> 1 | I27: =I19*$I$10 -> 0.14 | J27: =J19*$J$10 -> 0.26 | K27: =K19*$K$10 -> 0.5 | L27: =L19*$L$10 -> 0.1 | M27: =M19*$M$10 -> 0.22352941 | N27: =N19*$N$10 -> 0.53333333
A28: A3 | B28: =Концепции!$B$6 -> Система онлайн-бронирования услуг и управления записями | C28: =C20*$C$10 -> 0.49 | D28: =D20*$D$10 -> 0.75 | E28: =E20*$E$10 -> 1 | F28: =F20*$F$10 -> 0.36 | G28: =G20*$G$10 -> 0.72222222 | H28: =H20*$H$10 -> 1 | I28: =I20*$I$10 -> 0.15555556 | J28: =J20*$J$10 -> 0.325 | K28: =K20*$K$10 -> 1 | L28: =L20*$L$10 -> 0.088888889 | M28: =M20*$M$10 -> 0.22352941 | N28: =N20*$N$10 -> 0.8
A29: A4 | B29: =Концепции!$B$7 -> Система планирования тренировок и отслеживания физической активности | C29: =C21*$C$10 -> 0.35 | D29: =D21*$D$10 -> 0.69 | E29: =E21*$E$10 -> 1 | F29: =F21*$F$10 -> 0.18 | G29: =G21*$G$10 -> 0.58333333 | H29: =H21*$H$10 -> 0.9 | I29: =I21*$I$10 -> 0.2 | J29: =J21*$J$10 -> 0.37142857 | K29: =K21*$K$10 -> 1 | L29: =L21*$L$10 -> 0.11428571 | M29: =M21*$M$10 -> 0.25333333 | N29: =N21*$N$10 -> 0.8
A30: A* | B30: Идеальное решение | C30: =MAX(E26:E29) -> 1 | D30: =MAX(E26:E29) -> 1 | E30: =MAX(E26:E29) -> 1 | F30: =MAX(H26:H29) -> 1 | G30: =MAX(H26:H29) -> 1 | H30: =MAX(H26:H29) -> 1 | I30: =MAX(K26:K29) -> 1 | J30: =MAX(K26:K29) -> 1 | K30: =MAX(K26:K29) -> 1 | L30: =MAX(N26:N29) -> 0.8 | M30: =MAX(N26:N29) -> 0.8 | N30: =MAX(N26:N29) -> 0.8
A31: A⁻ | B31: Антиидеальное решение | C31: =MIN(C26:C29) -> 0.35 | D31: =MIN(C26:C29) -> 0.35 | E31: =MIN(C26:C29) -> 0.35 | F31: =MIN(F26:F29) -> 0.18 | G31: =MIN(F26:F29) -> 0.18 | H31: =MIN(F26:F29) -> 0.18 | I31: =MIN(I26:I29) -> 0.14 | J31: =MIN(I26:I29) -> 0.14 | K31: =MIN(I26:I29) -> 0.14 | L31: =MIN(L26:L29) -> 0.088888889 | M31: =MIN(L26:L29) -> 0.088888889 | N31: =MIN(L26:L29) -> 0.088888889
A33: 4. Расстояния до A* и A⁻, коэффициент близости
B34: Концепция | C34: d*(K1) | D34: d*(K2) | E34: d*(K3) | F34: d*(K4) | G34: D* | H34: d⁻(K1) | I34: d⁻(K2) | J34: d⁻(K3) | K34: d⁻(K4) | L34: D⁻ | M34: CC | N34: Ранг
A35: A1 | B35: =Концепции!$B$4 -> Система управления командными задачами и рабочими процессами | C35: =SQRT(((C26-C$30)^2+(D26-D$30)^2+(E26-E$30)^2)/3) -> 0.42351702 | D35: =SQRT(((F26-F$30)^2+(G26-G$30)^2+(H26-H$30)^2)/3) -> 0.45475313 | E35: =SQRT(((I26-I$30)^2+(J26-J$30)^2+(K26-K$30)^2)/3) -> 0.61542668 | F35: =SQRT(((L26-L$30)^2+(M26-M$30)^2+(N26-N$30)^2)/3) -> 0.54571954 | G35: =SUM(C35:F35) -> 2.0394164 | H35: =SQRT(((C26-C$31)^2+(D26-D$31)^2+(E26-E$31)^2)/3) -> 0.41577237 | I35: =SQRT(((F26-F$31)^2+(G26-G$31)^2+(H26-H$31)^2)/3) -> 0.54692443 | J35: =SQRT(((I26-I$31)^2+(J26-J$31)^2+(K26-K$31)^2)/3) -> 0.50828142 | K35: =SQRT(((L26-L$31)^2+(M26-M$31)^2+(N26-N$31)^2)/3) -> 0.26819296 | L35: =SUM(H35:K35) -> 1.7391712 | M35: =L35/(G35+L35) -> 0.46027018 | N35: =RANK(M35,$M$35:$M$38) -> 3
A36: A2 | B36: =Концепции!$B$5 -> Система персонального и семейного финансового учёта | C36: =SQRT(((C27-C$30)^2+(D27-D$30)^2+(E27-E$30)^2)/3) -> 0.31421861 | D36: =SQRT(((F27-F$30)^2+(G27-G$30)^2+(H27-H$30)^2)/3) -> 0.32648773 | E36: =SQRT(((I27-I$30)^2+(J27-J$30)^2+(K27-K$30)^2)/3) -> 0.71582121 | F36: =SQRT(((L27-L$30)^2+(M27-M$30)^2+(N27-N$30)^2)/3) -> 0.54571954 | G36: =SUM(C36:F36) -> 1.9022471 | H36: =SQRT(((C27-C$31)^2+(D27-D$31)^2+(E27-E$31)^2)/3) -> 0.4667976 | I36: =SQRT(((F27-F$31)^2+(G27-G$31)^2+(H27-H$31)^2)/3) -> 0.6109387 | J36: =SQRT(((I27-I$31)^2+(J27-J$31)^2+(K27-K$31)^2)/3) -> 0.21908902 | K36: =SQRT(((L27-L$31)^2+(M27-M$31)^2+(N27-N$31)^2)/3) -> 0.26819296 | L36: =SUM(H36:K36) -> 1.5650183 | M36: =L36/(G36+L36) -> 0.45136963 | N36: =RANK(M36,$M$35:$M$38) -> 4
A37: A3 | B37: =Концепции!$B$6 -> Система онлайн-бронирования услуг и управления записями | C37: =SQRT(((C28-C$30)^2+(D28-D$30)^2+(E28-E$30)^2)/3) -> 0.32792276 | D37: =SQRT(((F28-F$30)^2+(G28-G$30)^2+(H28-H$30)^2)/3) -> 0.40280702 | E37: =SQRT(((I28-I$30)^2+(J28-J$30)^2+(K28-K$30)^2)/3) -> 0.62415581 | F37: =SQRT(((L28-L$30)^2+(M28-M$30)^2+(N28-N$30)^2)/3) -> 0.52851911 | G37: =SUM(C37:F37) -> 1.8834047 | H37: =SQRT(((C28-C$31)^2+(D28-D$31)^2+(E28-E$31)^2)/3) -> 0.44799554 | I37: =SQRT(((F28-F$31)^2+(G28-G$31)^2+(H28-H$31)^2)/3) -> 0.57700518 | J37: =SQRT(((I28-I$31)^2+(J28-J$31)^2+(K28-K$31)^2)/3) -> 0.50795898 | K37: =SQRT(((L28-L$31)^2+(M28-M$31)^2+(N28-N$31)^2)/3) -> 0.41785447 | L37: =SUM(H37:K37) -> 1.9508142 | M37: =L37/(G37+L37) -> 0.50879051 | N37: =RANK(M37,$M$35:$M$38) -> 1
A38: A4 | B38: =Концепции!$B$7 -> Система планирования тренировок и отслеживания физической активности | C38: =SQRT(((C29-C$30)^2+(D29-D$30)^2+(E29-E$30)^2)/3) -> 0.41577237 | D38: =SQRT(((F29-F$30)^2+(G29-G$30)^2+(H29-H$30)^2)/3) -> 0.53416948 | E38: =SQRT(((I29-I$30)^2+(J29-J$30)^2+(K29-K$30)^2)/3) -> 0.58739596 | F38: =SQRT(((L29-L$30)^2+(M29-M$30)^2+(N29-N$30)^2)/3) -> 0.5063097 | G38: =SUM(C38:F38) -> 2.0436475 | H38: =SQRT(((C29-C$31)^2+(D29-D$31)^2+(E29-E$31)^2)/3) -> 0.42351702 | I38: =SQRT(((F29-F$31)^2+(G29-G$31)^2+(H29-H$31)^2)/3) -> 0.47647238 | J38: =SQRT(((I29-I$31)^2+(J29-J$31)^2+(K29-K$31)^2)/3) -> 0.51535075 | K38: =SQRT(((L29-L$31)^2+(M29-M$31)^2+(N29-N$31)^2)/3) -> 0.42164993 | L38: =SUM(H38:K38) -> 1.8369901 | M38: =L38/(G38+L38) -> 0.47337326 | N38: =RANK(M38,$M$35:$M$38) -> 2

Sheet МАИ
A1: Метод анализа иерархий (шкала Саати)
A2: Иерархия: цель «Выбор концепции проекта» → критерии K1–K4 → концепции A1–A4. Заполняется только верхний треугольник.
A3: Коллективное правило: средние m трёх экспертов; для K3–K4 меньшее значение лучше; сила предпочтения = 1 + округлённая разница, максимум 9.
A4: Критерии: парные сравнения важности
C5: =Концепции!$B$11 -> Пользовательская ценность | D5: =Концепции!$B$12 -> Широта целевой аудитории | E5: =Концепции!$B$13 -> Сложность освоения продукта | F5: =Концепции!$B$14 -> Количество действий для выполнения основных сценариев | G5: Ср. геом. | H5: Вес
A6: K1 | B6: =Концепции!$B$11 -> Пользовательская ценность | C6: 1 | D6: 2 | E6: 1 | F6: 4 | G6: =IF(COUNT(D6,E6,F6,E7,F7,F8)=6,PRODUCT(C6:F6)^(1/4),"") -> 1.6817928 | H6: =IF(COUNT(D6,E6,F6,E7,F7,F8)=6,G6/SUM($G$6:$G$9),"") -> 0.37267194
A7: K2 | B7: =Концепции!$B$12 -> Широта целевой аудитории | C7: =IF(D6="","",1/D6) -> 0.5 | D7: 1 | E7: 1 | F7: 3 | G7: =IF(COUNT(D6,E6,F6,E7,F7,F8)=6,PRODUCT(C7:F7)^(1/4),"") -> 1.1066819 | H7: =IF(COUNT(D6,E6,F6,E7,F7,F8)=6,G7/SUM($G$6:$G$9),"") -> 0.24523193
A8: K3 | B8: =Концепции!$B$13 -> Сложность освоения продукта | C8: =IF(E6="","",1/E6) -> 1 | D8: =IF(E7="","",1/E7) -> 1 | E8: 1 | F8: 3 | G8: =IF(COUNT(D6,E6,F6,E7,F7,F8)=6,PRODUCT(C8:F8)^(1/4),"") -> 1.316074 | H8: =IF(COUNT(D6,E6,F6,E7,F7,F8)=6,G8/SUM($G$6:$G$9),"") -> 0.29163155
A9: K4 | B9: =Концепции!$B$14 -> Количество действий для выполнения основных сценариев | C9: =IF(F6="","",1/F6) -> 0.25 | D9: =IF(F7="","",1/F7) -> 0.33333333 | E9: =IF(F8="","",1/F8) -> 0.33333333 | F9: 1 | G9: =IF(COUNT(D6,E6,F6,E7,F7,F8)=6,PRODUCT(C9:F9)^(1/4),"") -> 0.40824829 | H9: =IF(COUNT(D6,E6,F6,E7,F7,F8)=6,G9/SUM($G$6:$G$9),"") -> 0.09046458
B10: Сумма столбца | C10: =IF(COUNT(D6,E6,F6,E7,F7,F8)=6,SUM(C6:C9),"") -> 2.75 | D10: =IF(COUNT(D6,E6,F6,E7,F7,F8)=6,SUM(D6:D9),"") -> 4.3333333 | E10: =IF(COUNT(D6,E6,F6,E7,F7,F8)=6,SUM(E6:E9),"") -> 3.3333333 | F10: =IF(COUNT(D6,E6,F6,E7,F7,F8)=6,SUM(F6:F9),"") -> 11
B11: λmax | C11: =IF(COUNT(D6,E6,F6,E7,F7,F8)=6,C10*H6+D10*H7+E10*H8+F10*H9,"") -> 4.0547351
B12: ИС = (λmax−n)/(n−1) | C12: =IF(COUNT(D6,E6,F6,E7,F7,F8)=6,(C11-4)/(4-1),"") -> 0.018245026
B13: ОС = ИС / СИ (СИ = 0,90) | C13: =IF(COUNT(D6,E6,F6,E7,F7,F8)=6,C12/0.9,"") -> 0.020272251 | D13: =IF(COUNT(D6,E6,F6,E7,F7,F8)=6,IF(C13<=0.1,"согласовано","пересмотреть"),"ожидает сравнений") -> согласовано
A16: Концепции по критерию K1 | E16: =Концепции!$B$11 -> Пользовательская ценность
C17: =Концепции!$B$4 -> Система управления командными задачами и рабочими процессами | D17: =Концепции!$B$5 -> Система персонального и семейного финансового учёта | E17: =Концепции!$B$6 -> Система онлайн-бронирования услуг и управления записями | F17: =Концепции!$B$7 -> Система планирования тренировок и отслеживания физической активности | G17: Ср. геом. | H17: Вес
A18: A1 | B18: =Концепции!$B$4 -> Система управления командными задачами и рабочими процессами | C18: 1 | D18: 0.33333333 | E18: 0.5 | F18: 1 | G18: =IF(COUNT(D18,E18,F18,E19,F19,F20)=6,PRODUCT(C18:F18)^(1/4),"") -> 0.6389431 | H18: =IF(COUNT(D18,E18,F18,E19,F19,F20)=6,G18/SUM($G$18:$G$21),"") -> 0.14533105
A19: A2 | B19: =Концепции!$B$5 -> Система персонального и семейного финансового учёта | C19: =IF(D18="","",1/D18) -> 3 | D19: 1 | E19: 2 | F19: 2 | G19: =IF(COUNT(D18,E18,F18,E19,F19,F20)=6,PRODUCT(C19:F19)^(1/4),"") -> 1.8612097 | H19: =IF(COUNT(D18,E18,F18,E19,F19,F20)=6,G19/SUM($G$18:$G$21),"") -> 0.42334216
A20: A3 | B20: =Концепции!$B$6 -> Система онлайн-бронирования услуг и управления записями | C20: =IF(E18="","",1/E18) -> 2 | D20: =IF(E19="","",1/E19) -> 0.5 | E20: 1 | F20: 2 | G20: =IF(COUNT(D18,E18,F18,E19,F19,F20)=6,PRODUCT(C20:F20)^(1/4),"") -> 1.1892071 | H20: =IF(COUNT(D18,E18,F18,E19,F19,F20)=6,G20/SUM($G$18:$G$21),"") -> 0.27049155
A21: A4 | B21: =Концепции!$B$7 -> Система планирования тренировок и отслеживания физической активности | C21: =IF(F18="","",1/F18) -> 1 | D21: =IF(F19="","",1/F19) -> 0.5 | E21: =IF(F20="","",1/F20) -> 0.5 | F21: 1 | G21: =IF(COUNT(D18,E18,F18,E19,F19,F20)=6,PRODUCT(C21:F21)^(1/4),"") -> 0.70710678 | H21: =IF(COUNT(D18,E18,F18,E19,F19,F20)=6,G21/SUM($G$18:$G$21),"") -> 0.16083524
B22: Сумма столбца | C22: =IF(COUNT(D18,E18,F18,E19,F19,F20)=6,SUM(C18:C21),"") -> 7 | D22: =IF(COUNT(D18,E18,F18,E19,F19,F20)=6,SUM(D18:D21),"") -> 2.3333333 | E22: =IF(COUNT(D18,E18,F18,E19,F19,F20)=6,SUM(E18:E21),"") -> 4 | F22: =IF(COUNT(D18,E18,F18,E19,F19,F20)=6,SUM(F18:F21),"") -> 6
B23: λmax | C23: =IF(COUNT(D18,E18,F18,E19,F19,F20)=6,C22*H18+D22*H19+E22*H20+F22*H21,"") -> 4.0520933
B24: ИС = (λmax−n)/(n−1) | C24: =IF(COUNT(D18,E18,F18,E19,F19,F20)=6,(C23-4)/(4-1),"") -> 0.01736445
B25: ОС = ИС / СИ (СИ = 0,90) | C25: =IF(COUNT(D18,E18,F18,E19,F19,F20)=6,C24/0.9,"") -> 0.019293833 | D25: =IF(COUNT(D18,E18,F18,E19,F19,F20)=6,IF(C25<=0.1,"согласовано","пересмотреть"),"ожидает сравнений") -> согласовано
A29: Концепции по критерию K2 | E29: =Концепции!$B$12 -> Широта целевой аудитории
C30: =Концепции!$B$4 -> Система управления командными задачами и рабочими процессами | D30: =Концепции!$B$5 -> Система персонального и семейного финансового учёта | E30: =Концепции!$B$6 -> Система онлайн-бронирования услуг и управления записями | F30: =Концепции!$B$7 -> Система планирования тренировок и отслеживания физической активности | G30: Ср. геом. | H30: Вес
A31: A1 | B31: =Концепции!$B$4 -> Система управления командными задачами и рабочими процессами | C31: 1 | D31: 0.33333333 | E31: 0.5 | F31: 2 | G31: =IF(COUNT(D31,E31,F31,E32,F32,F33)=6,PRODUCT(C31:F31)^(1/4),"") -> 0.75983569 | H31: =IF(COUNT(D31,E31,F31,E32,F32,F33)=6,G31/SUM($G$31:$G$34),"") -> 0.16442501
A32: A2 | B32: =Концепции!$B$5 -> Система персонального и семейного финансового учёта | C32: =IF(D31="","",1/D31) -> 3 | D32: 1 | E32: 2 | F32: 3 | G32: =IF(COUNT(D31,E31,F31,E32,F32,F33)=6,PRODUCT(C32:F32)^(1/4),"") -> 2.0597671 | H32: =IF(COUNT(D31,E31,F31,E32,F32,F33)=6,G32/SUM($G$31:$G$34),"") -> 0.4457243
A33: A3 | B33: =Концепции!$B$6 -> Система онлайн-бронирования услуг и управления записями | C33: =IF(E31="","",1/E31) -> 2 | D33: =IF(E32="","",1/E32) -> 0.5 | E33: 1 | F33: 3 | G33: =IF(COUNT(D31,E31,F31,E32,F32,F33)=6,PRODUCT(C33:F33)^(1/4),"") -> 1.316074 | H33: =IF(COUNT(D31,E31,F31,E32,F32,F33)=6,G33/SUM($G$31:$G$34),"") -> 0.28479247
A34: A4 | B34: =Концепции!$B$7 -> Система планирования тренировок и отслеживания физической активности | C34: =IF(F31="","",1/F31) -> 0.5 | D34: =IF(F32="","",1/F32) -> 0.33333333 | E34: =IF(F33="","",1/F33) -> 0.33333333 | F34: 1 | G34: =IF(COUNT(D31,E31,F31,E32,F32,F33)=6,PRODUCT(C34:F34)^(1/4),"") -> 0.48549177 | H34: =IF(COUNT(D31,E31,F31,E32,F32,F33)=6,G34/SUM($G$31:$G$34),"") -> 0.10505822
B35: Сумма столбца | C35: =IF(COUNT(D31,E31,F31,E32,F32,F33)=6,SUM(C31:C34),"") -> 6.5 | D35: =IF(COUNT(D31,E31,F31,E32,F32,F33)=6,SUM(D31:D34),"") -> 2.1666667 | E35: =IF(COUNT(D31,E31,F31,E32,F32,F33)=6,SUM(E31:E34),"") -> 3.8333333 | F35: =IF(COUNT(D31,E31,F31,E32,F32,F33)=6,SUM(F31:F34),"") -> 9
B36: λmax | C36: =IF(COUNT(D31,E31,F31,E32,F32,F33)=6,C35*H31+D35*H32+E35*H33+F35*H34,"") -> 4.071727
B37: ИС = (λmax−n)/(n−1) | C37: =IF(COUNT(D31,E31,F31,E32,F32,F33)=6,(C36-4)/(4-1),"") -> 0.023909006
B38: ОС = ИС / СИ (СИ = 0,90) | C38: =IF(COUNT(D31,E31,F31,E32,F32,F33)=6,C37/0.9,"") -> 0.026565562 | D38: =IF(COUNT(D31,E31,F31,E32,F32,F33)=6,IF(C38<=0.1,"согласовано","пересмотреть"),"ожидает сравнений") -> согласовано
A42: Концепции по критерию K3 | E42: =Концепции!$B$13 -> Сложность освоения продукта
C43: =Концепции!$B$4 -> Система управления командными задачами и рабочими процессами | D43: =Концепции!$B$5 -> Система персонального и семейного финансового учёта | E43: =Концепции!$B$6 -> Система онлайн-бронирования услуг и управления записями | F43: =Концепции!$B$7 -> Система планирования тренировок и отслеживания физической активности | G43: Ср. геом. | H43: Вес
A44: A1 | B44: =Концепции!$B$4 -> Система управления командными задачами и рабочими процессами | C44: 1 | D44: 2 | E44: 1 | F44: 0.5 | G44: =IF(COUNT(D44,E44,F44,E45,F45,F46)=6,PRODUCT(C44:F44)^(1/4),"") -> 1 | H44: =IF(COUNT(D44,E44,F44,E45,F45,F46)=6,G44/SUM($G$44:$G$47),"") -> 0.22735051
A45: A2 | B45: =Концепции!$B$5 -> Система персонального и семейного финансового учёта | C45: =IF(D44="","",1/D44) -> 0.5 | D45: 1 | E45: 0.5 | F45: 0.33333333 | G45: =IF(COUNT(D44,E44,F44,E45,F45,F46)=6,PRODUCT(C45:F45)^(1/4),"") -> 0.53728497 | H45: =IF(COUNT(D44,E44,F44,E45,F45,F46)=6,G45/SUM($G$44:$G$47),"") -> 0.12215201
A46: A3 | B46: =Концепции!$B$6 -> Система онлайн-бронирования услуг и управления записями | C46: =IF(E44="","",1/E44) -> 1 | D46: =IF(E45="","",1/E45) -> 2 | E46: 1 | F46: 0.5 | G46: =IF(COUNT(D44,E44,F44,E45,F45,F46)=6,PRODUCT(C46:F46)^(1/4),"") -> 1 | H46: =IF(COUNT(D44,E44,F44,E45,F45,F46)=6,G46/SUM($G$44:$G$47),"") -> 0.22735051
A47: A4 | B47: =Концепции!$B$7 -> Система планирования тренировок и отслеживания физической активности | C47: =IF(F44="","",1/F44) -> 2 | D47: =IF(F45="","",1/F45) -> 3 | E47: =IF(F46="","",1/F46) -> 2 | F47: 1 | G47: =IF(COUNT(D44,E44,F44,E45,F45,F46)=6,PRODUCT(C47:F47)^(1/4),"") -> 1.8612097 | H47: =IF(COUNT(D44,E44,F44,E45,F45,F46)=6,G47/SUM($G$44:$G$47),"") -> 0.42314697
B48: Сумма столбца | C48: =IF(COUNT(D44,E44,F44,E45,F45,F46)=6,SUM(C44:C47),"") -> 4.5 | D48: =IF(COUNT(D44,E44,F44,E45,F45,F46)=6,SUM(D44:D47),"") -> 8 | E48: =IF(COUNT(D44,E44,F44,E45,F45,F46)=6,SUM(E44:E47),"") -> 4.5 | F48: =IF(COUNT(D44,E44,F44,E45,F45,F46)=6,SUM(F44:F47),"") -> 2.3333333
...

Sheet Итог
A1: Итог фазы 1
A3: Код | B3: Концепция | C3: TOPSIS: CC | D3: TOPSIS: ранг | E3: МАИ: приоритет | F3: МАИ: ранг | G3: Сумма рангов
A4: A1 | B4: =Концепции!$B$4 -> Система управления командными задачами и рабочими процессами | C4: =TOPSIS!M35 -> 0.46027018 | D4: =TOPSIS!N35 -> 3 | E4: =IF(МАИ!G70="","",МАИ!G70) -> 0.17887856 | F4: =IF(МАИ!H70="","",МАИ!H70) -> 4 | G4: =IF(COUNT(D4,F4)=2,D4+F4,"") -> 7
A5: A2 | B5: =Концепции!$B$5 -> Система персонального и семейного финансового учёта | C5: =TOPSIS!M36 -> 0.45136963 | D5: =TOPSIS!N36 -> 4 | E5: =IF(МАИ!G71="","",МАИ!G71) -> 0.32078987 | F5: =IF(МАИ!H71="","",МАИ!H71) -> 1 | G5: =IF(COUNT(D5,F5)=2,D5+F5,"") -> 5
A6: A3 | B6: =Концепции!$B$6 -> Система онлайн-бронирования услуг и управления записями | C6: =TOPSIS!M37 -> 0.50879051 | D6: =TOPSIS!N37 -> 1 | E6: =IF(МАИ!G72="","",МАИ!G72) -> 0.25504032 | F6: =IF(МАИ!H72="","",МАИ!H72) -> 2 | G6: =IF(COUNT(D6,F6)=2,D6+F6,"") -> 3
A7: A4 | B7: =Концепции!$B$7 -> Система планирования тренировок и отслеживания физической активности | C7: =TOPSIS!M38 -> 0.47337326 | D7: =TOPSIS!N38 -> 2 | E7: =IF(МАИ!G73="","",МАИ!G73) -> 0.24529125 | F7: =IF(МАИ!H73="","",МАИ!H73) -> 3 | G7: =IF(COUNT(D7,F7)=2,D7+F7,"") -> 5
B10: Лучшая по TOPSIS | C10: =INDEX($B$4:$B$7,MATCH(MAX($C$4:$C$7),$C$4:$C$7,0)) -> Система онлайн-бронирования услуг и управления записями
B11: Лучшая по МАИ | C11: =IF(COUNT($E$4:$E$7)=4,INDEX($B$4:$B$7,MATCH(MAX($E$4:$E$7),$E$4:$E$7,0)),"ожидает МАИ") -> Система персонального и семейного финансового учёта
B12: Методы согласны? | C12: =IF(COUNT($E$4:$E$7)=4,IF(C10=C11,"да — выбрана "&C10,"нет — нужно обсуждение"),"ожидает МАИ") -> нет — нужно обсуждение
B14: Лучшая по сумме рангов | C14: =IF(COUNT(G4:G7)=4,INDEX(B4:B7,MATCH(MIN(G4:G7),G4:G7,0)),"ожидает МАИ") -> Система онлайн-бронирования услуг и управления записями
